Workbook

Sheet Floorplans
A1: Display name | B1: ID | C1: Manufacturer | D1: Series | E1: Version | F1: Category | G1: Model number | H1: Model name | I1: Bedrooms | J1: Bathrooms | K1: Sq ft | L1: Width (ft) | M1: Length (ft) | N1: Sections | O1: Size (original text) | P1: Show on kiosk | Q1: Why not shown | R1: Price | S1: Has 3D tour | T1: Floorplan PDF | U1: 360 rendering (Momento360) | V1: Matterport tour | W1: Other 3D tour | X1: Main photo | Y1: All photos (semicolon-separated) | Z1: Description | AA1: Construction specs | AB1: Exterior specs | AC1: Interior specs | AD1: Utilities specs | AE1: Kitchen & bath specs | AF1: In spreadsheet | AG1: In store catalog | AH1: Visible in store | AI1: Open review items
A2: Dream Silver Casita | B2: gw-dream-silver-casita | C2: Golden West | D2: Dream Silver | E2: Standard | F2: Floorplan | G2: 30-1 ADU | H2: Casita | I2: 1 | J2: 1 | K2: 409 | L2: 13.5 | M2: 38.33 | N2: Single | O2: 13' 6" WIDE | P2: Yes | S2: =IF(COUNTA(U2:W2)>0,"Yes","No") -> Yes | T2: https://raw.githubusercontent.com/CadelMVH/Wix-Gallery-Downloads/main/DRM/Casita.pdf | U2: https://momento360.com/e/uc/dcc793a4ecd5443eab27501b640cf53b | X2: https://static.wixstatic.com/media/866235_9c8d2709b61a478ebb1b659915750f8b~mv2.webp | Y2: https://static.wixstatic.com/media/866235_9c8d2709b61a478ebb1b659915750f8b~mv2.webp; https://static.wixstatic.com/media/866235_180ed77e6d0c4e489699bf325119ba07~mv2.webp | Z2: The Dream Silver / 30-1 ADU Casita built by Golden West Homes provides 409 square feet of efficiently crafted living space, featuring 1 bedroom and 1 bathroom. This manufactured home is perfect for those seeking a cozy yet functional layout, with an open area ideal for daily relaxation and a private bedroom that offers a restful escape. The 30-1 ADU Casita is an excellent choice for individuals or couples looking for a compact, modern home that combines practicality with a welcoming, comfortable atmosphere. | AA2: Additional Specs: In-Floor Waste Plumbing / Kiln Dried Framing Lumber / GFI Receptacle at all Wet Areas; Exterior Wall On Center: 16” O.C.; Exterior Wall Studs: 2'x6' Exterior Walls; Floor Decking: 19/32” OSB T&G Floor Decking; Floor Joists: 2x6 Floor Joists -16” O.C.; Roof Load: 30# Roof Load; Side Wall Height: 96” Sidewall (Flat Ceiling); Insulation (Floors): R-33; Insulation (Walls): R-21; Insulation (Ceiling): R-40 | AB2: Additional Specs: 2x8 Rough Sawn / Continuous Eave Soffit Venting / Ridge Style Roof Venting / Deadbolts on Front and Rear Doors; Front Door: 36” Front Doors; Rear Door: 36” Rear Doors; Roof Pitch: 3:12 (4:12 pitch single sections); Shingles: Architectural Shingles; Siding: LP Smart Panel Siding w/5/50 year warranty; Window Trim: 4” Window Trim; Window Type: Dual Pane Low-E Windows; Exterior Lighting: Porch Lights at each Exterior Entry; Front Rear Eaves: Exterior 14" Eaves Double wide, 6" Single wide; Exterior Outlets: Exterior 2 GFI Standard | AC2: Ceiling Texture: Brocade Style Ceiling Drywall Finish; Door Carpet Type: Entry Lino; Safety Alarms: Smoke Alarms, Bdrms & Living Areas; Window Type: Wood Window Interior Wrap / Egress Windows in all Bedrooms; Molding: Baseboard Molding in Lino Areas; Wall Finish: Tape and Texture Drywall Throughout / Square Sheetrock Corners; Interior Doors: 2-Panel Interior Doors; Carpet Type Or Grade: 5# Carpet Pad / New Wave 25oz Carpet | AD2: Electrical Service: 200 Amp Electrical Service; Electrical Wiring: All Copper Wiring; Furnace: Forced Air Elect Down Flow Furnace; Other: Receptacle at Fresh Water Inlet; Shut Off Valves Throughout: Whole House Shut-off Valve; Thermostat: EcoBee T-Stat; Washer Dryer Hook Up: Plumbed/Wire For Washer and Dryer; Water Heater: 40 Gallon Electric Water Heater; Water Shut Off Valves: Shut-Off Valves at Toilets & Sinks | AE2: Kitchen Sink: Kitchen Sink 8” Stainless Steel; Kitchen Refrigerator: Frigidaire 18 cu ft Refrigerator; Kitchen Range Type: Frigidaire Free Standing Range; Kitchen Range Hood: 30” Lighted Exhaust Fan over Range; Kitchen Lighting: Recessed Lights (Qty. Per Model); Kitchen Flooring: No-Wax Vinyl Flooring; Kitchen Faucets: Single Lever Faucet with Sprayer; Kitchen Countertops: Laminated Counter Tops / Crescent Edge T/Out; Kitchen Additional Specs: Fire Extinguisher Under Sink; Bathroom Sink: China Lavy Sinks; Bathroom Lighting: Recessed Lights (Per Model); Bathroom Flooring: No-Wax Vinyl Flooring; Bathroom Countertops: Laminated Counter Tops / Crescent Edge T/Out; Bathroom Faucets: Adjustable Shower Heads; Bathroom Fans: Exhaust Fans w/Light in each Bath; Bathroom Toilet Type: Elongated Toilets; Bathroom Bathtubs: 60” Fiberglass Tub/Shower in each Bath | AF2: Yes | AG2: Yes | AH2: Yes | AI2: =COUNTIF('Needs review'!$A:$A,B2) -> 0
A3: Dream Silver 401M | B3: gw-dream-silver-401m | C3: Golden West | D3: Dream Silver | E3: Standard | F3: Floorplan | G3: DRM 401M | I3: 1 | J3: 1 | K3: 540 | L3: 13.5 | M3: 40 | N3: Single | O3: 13' 6" WIDE | P3: Yes | S3: =IF(COUNTA(U3:W3)>0,"Yes","No") -> Yes | U3: https://momento360.com/e/uc/999746fb962b487c85886840fcc14234 | X3: https://static.wixstatic.com/media/866235_6da00937ee914326a828426428da3156~mv2.webp | Y3: https://static.wixstatic.com/media/866235_6da00937ee914326a828426428da3156~mv2.webp | Z3: The Dream Silver / DRM 401M built by Golden West Homes offers 540 square feet of thoughtfully designed living space, featuring 1 bedroom and 1 bathroom. This manufactured home maximizes compact living, with an efficient layout that provides a comfortable open area for daily living and a private bedroom that ensures a restful retreat. The DRM 401M is an ideal option for those seeking a modern, streamlined home that balances style and functionality, making it perfect for cozy living or a stylish escape. | AA3: Additional Specs: In-Floor Waste Plumbing / Kiln Dried Framing Lumber / GFI Receptacle at all Wet Areas; Exterior Wall On Center: 16” O.C.; Exterior Wall Studs: 2'x6' Exterior Walls; Floor Decking: 19/32” OSB T&G Floor Decking; Floor Joists: 2x6 Floor Joists -16” O.C.; Roof Load: 30# Roof Load; Side Wall Height: 96” Sidewall (Flat Ceiling); Insulation (Floors): R-33; Insulation (Walls): R-21; Insulation (Ceiling): R-40 | AB3: Additional Specs: 2x8 Rough Sawn / Continuous Eave Soffit Venting / Ridge Style Roof Venting / Deadbolts on Front and Rear Doors; Front Door: 36” Front Doors; Rear Door: 36” Rear Doors; Roof Pitch: 3:12 (4:12 pitch single sections); Shingles: Architectural Shingles; Siding: LP Smart Panel Siding w/5/50 year warranty; Window Trim: 4” Window Trim; Window Type: Dual Pane Low-E Windows; Exterior Lighting: Porch Lights at each Exterior Entry; Front Rear Eaves: Exterior 14" Eaves Double wide, 6" Single wide; Exterior Outlets: Exterior 2 GFI Standard | AC3: Ceiling Texture: Brocade Style Ceiling Drywall Finish; Door Carpet Type: Entry Lino; Safety Alarms: Smoke Alarms, Bdrms & Living Areas; Window Type: Wood Window Interior Wrap / Egress Windows in all Bedrooms; Molding: Baseboard Molding in Lino Areas; Wall Finish: Tape and Texture Drywall Throughout / Square Sheetrock Corners; Interior Doors: 2-Panel Interior Doors; Carpet Type Or Grade: 5# Carpet Pad / New Wave 25oz Carpet | AD3: Electrical Service: 200 Amp Electrical Service; Electrical Wiring: All Copper Wiring; Furnace: Forced Air Elect Down Flow Furnace; Other: Receptacle at Fresh Water Inlet; Shut Off Valves Throughout: Whole House Shut-off Valve; Thermostat: EcoBee T-Stat; Washer Dryer Hook Up: Plumbed/Wire For Washer and Dryer; Water Heater: 40 Gallon Electric Water Heater; Water Shut Off Valves: Shut-Off Valves at Toilets & Sinks | AE3: Kitchen Sink: Kitchen Sink 8” Stainless Steel; Kitchen Refrigerator: Frigidaire 18 cu ft Refrigerator; Kitchen Range Type: Frigidaire Free Standing Range; Kitchen Range Hood: 30” Lighted Exhaust Fan over Range; Kitchen Lighting: Recessed Lights (Qty. Per Model); Kitchen Flooring: No-Wax Vinyl Flooring; Kitchen Faucets: Single Lever Faucet with Sprayer; Kitchen Countertops: Laminated Counter Tops / Crescent Edge T/Out; Kitchen Additional Specs: Fire Extinguisher Under Sink; Bathroom Sink: China Lavy Sinks; Bathroom Lighting: Recessed Lights (Per Model); Bathroom Flooring: No-Wax Vinyl Flooring; Bathroom Countertops: Laminated Counter Tops / Crescent Edge T/Out; Bathroom Faucets: Adjustable Shower Heads; Bathroom Fans: Exhaust Fans w/Light in each Bath; Bathroom Toilet Type: Elongated Toilets; Bathroom Bathtubs: 60” Fiberglass Tub/Shower in each Bath | AF3: Yes | AG3: Yes | AH3: Yes | AI3: =COUNTIF('Needs review'!$A:$A,B3) -> 1
A4: Dream Silver 301P | B4: gw-dream-silver-301p | C4: Golden West | D4: Dream Silver | E4: Standard | F4: Floorplan | G4: DRM 301P | I4: 1 | J4: 1 | K4: 547 | L4: 20 | M4: 30 | N4: Double | O4: 20' WIDE | P4: Yes | S4: =IF(COUNTA(U4:W4)>0,"Yes","No") -> Yes | T4: https://raw.githubusercontent.com/CadelMVH/Wix-Gallery-Downloads/main/DRM/301P.pdf | U4: https://momento360.com/e/uc/ef300530b0e543a992478916e4be7d57 | X4: https://static.wixstatic.com/media/866235_bcc9274dcd004055ba80525c2dcf17eb~mv2.webp | Y4: https://static.wixstatic.com/media/866235_bcc9274dcd004055ba80525c2dcf17eb~mv2.webp; https://static.wixstatic.com/media/866235_5113cc8a7c0c4f5495c1c5811a5a4834~mv2.webp | Z4: The Dream Silver / DRM 301P built by Golden West Homes offers 547 square feet of efficiently designed living space, featuring 1 bedroom and 1 bathroom. This manufactured home maximizes comfort within a compact footprint, with an open living area that enhances functionality and a private bedroom that provides a restful retreat. The DRM 301P is an ideal choice for individuals or couples seeking a cozy, modern home that blends practicality with style, making it perfect for those who appreciate efficient, comfortable living. | AA4: Additional Specs: In-Floor Waste Plumbing / Kiln Dried Framing Lumber / GFI Receptacle at all Wet Areas; Exterior Wall On Center: 16” O.C.; Exterior Wall Studs: 2'x6' Exterior Walls; Floor Decking: 19/32” OSB T&G Floor Decking; Floor Joists: 2x6 Floor Joists -16” O.C.; Roof Load: 30# Roof Load; Side Wall Height: 96” Sidewall (Flat Ceiling); Insulation (Floors): R-33; Insulation (Walls): R-21; Insulation (Ceiling): R-40 | AB4: Additional Specs: 2x8 Rough Sawn / Continuous Eave Soffit Venting / Ridge Style Roof Venting / Deadbolts on Front and Rear Doors; Front Door: 36” Front Doors; Rear Door: 36” Rear Doors; Roof Pitch: 3:12 (4:12 pitch single sections); Shingles: Architectural Shingles; Siding: LP Smart Panel Siding w/5/50 year warranty; Window Trim: 4” Window Trim; Window Type: Dual Pane Low-E Windows; Exterior Lighting: Porch Lights at each Exterior Entry; Front Rear Eaves: Exterior 14" Eaves Double wide, 6" Single wide; Exterior Outlets: Exterior 2 GFI Standard | AC4: Ceiling Texture: Brocade Style Ceiling Drywall Finish; Door Carpet Type: Entry Lino; Safety Alarms: Smoke Alarms, Bdrms & Living Areas; Window Type: Wood Window Interior Wrap / Egress Windows in all Bedrooms; Molding: Baseboard Molding in Lino Areas; Wall Finish: Tape and Texture Drywall Throughout / Square Sheetrock Corners; Interior Doors: 2-Panel Interior Doors; Carpet Type Or Grade: 5# Carpet Pad / New Wave 25oz Carpet | AD4: Electrical Service: 200 Amp Electrical Service; Electrical Wiring: All Copper Wiring; Furnace: Forced Air Elect Down Flow Furnace; Other: Receptacle at Fresh Water Inlet; Shut Off Valves Throughout: Whole House Shut-off Valve; Thermostat: EcoBee T-Stat; Washer Dryer Hook Up: Plumbed/Wire For Washer and Dryer; Water Heater: 40 Gallon Electric Water Heater; Water Shut Off Valves: Shut-Off Valves at Toilets & Sinks | AE4: Kitchen Sink: Kitchen Sink 8” Stainless Steel; Kitchen Refrigerator: Frigidaire 18 cu ft Refrigerator; Kitchen Range Type: Frigidaire Free Standing Range; Kitchen Range Hood: 30” Lighted Exhaust Fan over Range; Kitchen Lighting: Recessed Lights (Qty. Per Model); Kitchen Flooring: No-Wax Vinyl Flooring; Kitchen Faucets: Single Lever Faucet with Sprayer; Kitchen Countertops: Laminated Counter Tops / Crescent Edge T/Out; Kitchen Additional Specs: Fire Extinguisher Under Sink; Bathroom Sink: China Lavy Sinks; Bathroom Lighting: Recessed Lights (Per Model); Bathroom Flooring: No-Wax Vinyl Flooring; Bathroom Countertops: Laminated Counter Tops / Crescent Edge T/Out; Bathroom Faucets: Adjustable Shower Heads; Bathroom Fans: Exhaust Fans w/Light in each Bath; Bathroom Toilet Type: Elongated Toilets; Bathroom Bathtubs: 60” Fiberglass Tub/Shower in each Bath | AF4: Yes | AG4: Yes | AH4: Yes | AI4: =COUNTIF('Needs review'!$A:$A,B4) -> 0
A5: Dream Silver 481M | B5: gw-dream-silver-481m | C5: Golden West | D5: Dream Silver | E5: Standard | F5: Floorplan | G5: DRM 481M | I5: 2 | J5: 1 | K5: 648 | L5: 13.5 | M5: 48 | N5: Single | O5: 13' 6" WIDE | P5: Yes | S5: =IF(COUNTA(U5:W5)>0,"Yes","No") -> Yes | T5: https://raw.githubusercontent.com/CadelMVH/Wix-Gallery-Downloads/main/DRM/481M.pdf | U5: https://momento360.com/e/uc/76f05bf3de0a4e5f9b2e5b03c47ce5c8 | X5: https://static.wixstatic.com/media/866235_c6ca4fc7e5b64058ba2e55542548fe99~mv2.webp | Y5: https://static.wixstatic.com/media/866235_c6ca4fc7e5b64058ba2e55542548fe99~mv2.webp; https://static.wixstatic.com/media/866235_ddb53fb332074daf9a216a19491433fd~mv2.webp; https://static.wixstatic.com/media/866235_7fe235120b5d423dba1b74eef517ff23~mv2.webp; https://static.wixstatic.com/media/866235_ce23bacb3de4418aaa21023b3a0d0a20~mv2.webp; https://static.wixstatic.com/media/866235_c392d7f58e974a2ca49923280a6c0ae4~mv2.webp; https://static.wixstatic.com/media/866235_83870faf8db44ad8a881d7b5651235cc~mv2.webp; https://static.wixstatic.com/media/866235_6b4d6779a66e410da1571f9cae425a43~mv2.webp | Z5: The Dream Silver / DRM 481M built by Golden West Homes offers 648 square feet of efficiently designed living space, featuring 2 bedrooms and 1 bathroom. This manufactured home makes the most of every square foot, with a smart layout that fosters both comfort and functionality, ideal for cozy living. The DRM 481M is a great choice for individuals or couples looking for a compact, contemporary home that provides a sense of style and purpose, making it a perfect fit for efficient everyday living or a welcoming retreat. | AA5: Additional Specs: In-Floor Waste Plumbing / Kiln Dried Framing Lumber / GFI Receptacle at all Wet Areas; Exterior Wall On Center: 16” O.C.; Exterior Wall Studs: 2'x6' Exterior Walls; Floor Decking: 19/32” OSB T&G Floor Decking; Floor Joists: 2x6 Floor Joists -16” O.C.; Roof Load: 30# Roof Load; Side Wall Height: 96” Sidewall (Flat Ceiling); Insulation (Floors): R-33; Insulation (Walls): R-21; Insulation (Ceiling): R-40 | AB5: Additional Specs: 2x8 Rough Sawn / Continuous Eave Soffit Venting / Ridge Style Roof Venting / Deadbolts on Front and Rear Doors; Front Door: 36” Front Doors; Rear Door: 36” Rear Doors; Roof Pitch: 3:12 (4:12 pitch single sections); Shingles: Architectural Shingles; Siding: LP Smart Panel Siding w/5/50 year warranty; Window Trim: 4” Window Trim; Window Type: Dual Pane Low-E Windows; Exterior Lighting: Porch Lights at each Exterior Entry; Front Rear Eaves: Exterior 14" Eaves Double wide, 6" Single wide; Exterior Outlets: Exterior 2 GFI Standard | AC5: Ceiling Texture: Brocade Style Ceiling Drywall Finish; Door Carpet Type: Entry Lino; Safety Alarms: Smoke Alarms, Bdrms & Living Areas; Window Type: Wood Window Interior Wrap / Egress Windows in all Bedrooms; Molding: Baseboard Molding in Lino Areas; Wall Finish: Tape and Texture Drywall Throughout / Square Sheetrock Corners; Interior Doors: 2-Panel Interior Doors; Carpet Type Or Grade: 5# Carpet Pad / New Wave 25oz Carpet | AD5: Electrical Service: 200 Amp Electrical Service; Electrical Wiring: All Copper Wiring; Furnace: Forced Air Elect Down Flow Furnace; Other: Receptacle at Fresh Water Inlet; Shut Off Valves Throughout: Whole House Shut-off Valve; Thermostat: EcoBee T-Stat; Washer Dryer Hook Up: Plumbed/Wire For Washer and Dryer; Water Heater: 40 Gallon Electric Water Heater; Water Shut Off Valves: Shut-Off Valves at Toilets & Sinks | AE5: Kitchen Sink: Kitchen Sink 8” Stainless Steel; Kitchen Refrigerator: Frigidaire 18 cu ft Refrigerator; Kitchen Range Type: Frigidaire Free Standing Range; Kitchen Range Hood: 30” Lighted Exhaust Fan over Range; Kitchen Lighting: Recessed Lights (Qty. Per Model); Kitchen Flooring: No-Wax Vinyl Flooring; Kitchen Faucets: Single Lever Faucet with Sprayer; Kitchen Countertops: Laminated Counter Tops / Crescent Edge T/Out; Kitchen Additional Specs: Fire Extinguisher Under Sink; Bathroom Sink: China Lavy Sinks; Bathroom Lighting: Recessed Lights (Per Model); Bathroom Flooring: No-Wax Vinyl Flooring; Bathroom Countertops: Laminated Counter Tops / Crescent Edge T/Out; Bathroom Faucets: Adjustable Shower Heads; Bathroom Fans: Exhaust Fans w/Light in each Bath; Bathroom Toilet Type: Elongated Toilets; Bathroom Bathtubs: 60” Fiberglass Tub/Shower in each Bath | AF5: Yes | AG5: Yes | AH5: Yes | AI5: =COUNTIF('Needs review'!$A:$A,B5) -> 0
A6: Dream Silver 521M | B6: gw-dream-silver-521m | C6: Golden West | D6: Dream Silver | E6: Standard | F6: Floorplan | G6: DRM 521M | I6: 2 | J6: 1 | K6: 702 | L6: 14 | M6: 52 | N6: Single | O6: 13' 6" WIDE | P6: Yes | S6: =IF(COUNTA(U6:W6)>0,"Yes","No") -> No | T6: https://raw.githubusercontent.com/CadelMVH/Wix-Gallery-Downloads/main/DRM/521M.pdf | X6: https://static.wixstatic.com/media/866235_922087d54c3142fab96a9b0d853664b0~mv2.webp | Y6: https://static.wixstatic.com/media/866235_922087d54c3142fab96a9b0d853664b0~mv2.webp; https://static.wixstatic.com/media/866235_78ff8acef6b04600a11862b5dba051d3~mv2.webp | Z6: The Dream Silver / DRM 521M built by Golden West Homes offers 702 square feet of efficient living space, featuring 2 bedrooms and 1 bathroom. This manufactured home is thoughtfully designed to maximize functionality within a compact layout, providing open areas for comfortable daily living and private bedrooms that offer a cozy retreat. The DRM 521M is an ideal choice for individuals or couples seeking a modern, compact home that blends practicality with a welcoming atmosphere, perfect for both short stays and long-term living. | AA6: Additional Specs: In-Floor Waste Plumbing / Kiln Dried Framing Lumber / GFI Receptacle at all Wet Areas; Exterior Wall On Center: 16” O.C.; Exterior Wall Studs: 2'x6' Exterior Walls; Floor Decking: 19/32” OSB T&G Floor Decking; Floor Joists: 2x6 Floor Joists -16” O.C.; Roof Load: 30# Roof Load; Side Wall Height: 96” Sidewall (Flat Ceiling); Insulation (Floors): R-33; Insulation (Walls): R-21; Insulation (Ceiling): R-40 | AB6: Additional Specs: 2x8 Rough Sawn / Continuous Eave Soffit Venting / Ridge Style Roof Venting / Deadbolts on Front and Rear Doors; Front Door: 36” Front Doors; Rear Door: 36” Rear Doors; Roof Pitch: 3:12 (4:12 pitch single sections); Shingles: Architectural Shingles; Siding: LP Smart Panel Siding w/5/50 year warranty; Window Trim: 4” Window Trim; Window Type: Dual Pane Low-E Windows; Exterior Lighting: Porch Lights at each Exterior Entry; Front Rear Eaves: Exterior 14" Eaves Double wide, 6" Single wide; Exterior Outlets: Exterior 2 GFI Standard | AC6: Ceiling Texture: Brocade Style Ceiling Drywall Finish; Door Carpet Type: Entry Lino; Safety Alarms: Smoke Alarms, Bdrms & Living Areas; Window Type: Wood Window Interior Wrap / Egress Windows in all Bedrooms; Molding: Baseboard Molding in Lino Areas; Wall Finish: Tape and Texture Drywall Throughout / Square Sheetrock Corners; Interior Doors: 2-Panel Interior Doors; Carpet Type Or Grade: 5# Carpet Pad / New Wave 25oz Carpet | AD6: Electrical Service: 200 Amp Electrical Service; Electrical Wiring: All Copper Wiring; Furnace: Forced Air Elect Down Flow Furnace; Other: Receptacle at Fresh Water Inlet; Shut Off Valves Throughout: Whole House Shut-off Valve; Thermostat: EcoBee T-Stat; Washer Dryer Hook Up: Plumbed/Wire For Washer and Dryer; Water Heater: 40 Gallon Electric Water Heater; Water Shut Off Valves: Shut-Off Valves at Toilets & Sinks | AE6: Kitchen Sink: Kitchen Sink 8” Stainless Steel; Kitchen Refrigerator: Frigidaire 18 cu ft Refrigerator; Kitchen Range Type: Frigidaire Free Standing Range; Kitchen Range Hood: 30” Lighted Exhaust Fan over Range; Kitchen Lighting: Recessed Lights (Qty. Per Model); Kitchen Flooring: No-Wax Vinyl Flooring; Kitchen Faucets: Single Lever Faucet with Sprayer; Kitchen Countertops: Laminated Counter Tops / Crescent Edge T/Out; Kitchen Additional Specs: Fire Extinguisher Under Sink; Bathroom Sink: China Lavy Sinks; Bathroom Lighting: Recessed Lights (Per Model); Bathroom Flooring: No-Wax Vinyl Flooring; Bathroom Countertops: Laminated Counter Tops / Crescent Edge T/Out; Bathroom Faucets: Adjustable Shower Heads; Bathroom Fans: Exhaust Fans w/Light in each Bath; Bathroom Toilet Type: Elongated Toilets; Bathroom Bathtubs: 60” Fiberglass Tub/Shower in each Bath | AF6: Yes | AG6: Yes | AH6: Yes | AI6: =COUNTIF('Needs review'!$A:$A,B6) -> 0
A7: Dream Silver 561M | B7: gw-dream-silver-561m | C7: Golden West | D7: Dream Silver | E7: Standard | F7: Floorplan | G7: DRM 561M | I7: 2 | J7: 1 | K7: 756 | L7: 14 | M7: 56 | N7: Single | O7: 13' 6" WIDE | P7: Yes | S7: =IF(COUNTA(U7:W7)>0,"Yes","No") -> Yes | T7: https://raw.githubusercontent.com/CadelMVH/Wix-Gallery-Downloads/main/DRM/561M.pdf | U7: https://momento360.com/e/uc/1e50ee51532140168e6d78c231a912b3 | X7: https://static.wixstatic.com/media/866235_579e0afb28c04b948113103ece5efb72~mv2.webp | Y7: https://static.wixstatic.com/media/866235_579e0afb28c04b948113103ece5efb72~mv2.webp; https://static.wixstatic.com/media/866235_db9ead3354564a06bebb40edb426ab00~mv2.webp | Z7: The Dream Silver / DRM 561M built by Golden West Homes offers 756 square feet of efficiently designed living space, featuring 2 bedrooms and 1 bathroom. This manufactured home combines functionality with style, providing an open layout ideal for comfortable living and private bedrooms that ensure a cozy retreat. The DRM 561M is a fantastic option for individuals or couples seeking a modern, compact home that balances convenience with warmth, making it perfect for those who value both practicality and comfort. | AA7: Additional Specs: In-Floor Waste Plumbing / Kiln Dried Framing Lumber / GFI Receptacle at all Wet Areas; Exterior Wall On Center: 16” O.C.; Exterior Wall Studs: 2'x6' Exterior Walls; Floor Decking: 19/32” OSB T&G Floor Decking; Floor Joists: 2x6 Floor Joists -16” O.C.; Roof Load: 30# Roof Load; Side Wall Height: 96” Sidewall (Flat Ceiling); Insulation (Floors): R-33; Insulation (Walls): R-21; Insulation (Ceiling): R-40 | AB7: Additional Specs: 2x8 Rough Sawn / Continuous Eave Soffit Venting / Ridge Style Roof Venting / Deadbolts on Front and Rear Doors; Front Door: 36” Front Doors; Rear Door: 36” Rear Doors; Roof Pitch: 3:12 (4:12 pitch single sections); Shingles: Architectural Shingles; Siding: LP Smart Panel Siding w/5/50 year warranty; Window Trim: 4” Window Trim; Window Type: Dual Pane Low-E Windows; Exterior Lighting: Porch Lights at each Exterior Entry; Front Rear Eaves: Exterior 14" Eaves Double wide, 6" Single wide; Exterior Outlets: Exterior 2 GFI Standard | AC7: Ceiling Texture: Brocade Style Ceiling Drywall Finish; Door Carpet Type: Entry Lino; Safety Alarms: Smoke Alarms, Bdrms & Living Areas; Window Type: Wood Window Interior Wrap / Egress Windows in all Bedrooms; Molding: Baseboard Molding in Lino Areas; Wall Finish: Tape and Texture Drywall Throughout / Square Sheetrock Corners; Interior Doors: 2-Panel Interior Doors; Carpet Type Or Grade: 5# Carpet Pad / New Wave 25oz Carpet | AD7: Electrical Service: 200 Amp Electrical Service; Electrical Wiring: All Copper Wiring; Furnace: Forced Air Elect Down Flow Furnace; Other: Receptacle at Fresh Water Inlet; Shut Off Valves Throughout: Whole House Shut-off Valve; Thermostat: EcoBee T-Stat; Washer Dryer Hook Up: Plumbed/Wire For Washer and Dryer; Water Heater: 40 Gallon Electric Water Heater; Water Shut Off Valves: Shut-Off Valves at Toilets & Sinks | AE7: Kitchen Sink: Kitchen Sink 8” Stainless Steel; Kitchen Refrigerator: Frigidaire 18 cu ft Refrigerator; Kitchen Range Type: Frigidaire Free Standing Range; Kitchen Range Hood: 30” Lighted Exhaust Fan over Range; Kitchen Lighting: Recessed Lights (Qty. Per Model); Kitchen Flooring: No-Wax Vinyl Flooring; Kitchen Faucets: Single Lever Faucet with Sprayer; Kitchen Countertops: Laminated Counter Tops / Crescent Edge T/Out; Kitchen Additional Specs: Fire Extinguisher Under Sink; Bathroom Sink: China Lavy Sinks; Bathroom Lighting: Recessed Lights (Per Model); Bathroom Flooring: No-Wax Vinyl Flooring; Bathroom Countertops: Laminated Counter Tops / Crescent Edge T/Out; Bathroom Faucets: Adjustable Shower Heads; Bathroom Fans: Exhaust Fans w/Light in each Bath; Bathroom Toilet Type: Elongated Toilets; Bathroom Bathtubs: 60” Fiberglass Tub/Shower in each Bath | AF7: Yes | AG7: Yes | AH7: Yes | AI7: =COUNTIF('Needs review'!$A:$A,B7) -> 0
A8: Dream Silver 402P | B8: gw-dream-silver-402p | C8: Golden West | D8: Dream Silver | E8: Standard | F8: Floorplan | G8: DRM 402P | I8: 2 | J8: 2 | K8: 800 | L8: 20 | M8: 40 | N8: Double | O8: 20' WIDE | P8: Yes | S8: =IF(COUNTA(U8:W8)>0,"Yes","No") -> No | T8: https://raw.githubusercontent.com/CadelMVH/Wix-Gallery-Downloads/main/DRM/402P.pdf | X8: https://static.wixstatic.com/media/866235_6b17783274284ee284b3af18c0ff5630~mv2.webp | Y8: https://static.wixstatic.com/media/866235_6b17783274284ee284b3af18c0ff5630~mv2.webp; https://static.wixstatic.com/media/866235_18f79ac33f7b4b3dad4f47a6354a4fa8~mv2.webp | Z8: The Dream Silver / DRM 402P built by Golden West Homes offers 800 square feet of carefully designed living space, featuring 2 bedrooms and 2 bathrooms. This manufactured home is ideal for those seeking a balance of style and function, with an open layout that maximizes comfort and private bedrooms that create a cozy retreat. The DRM 402P is a perfect choice for individuals or couples looking for a compact, modern home that combines practicality with a warm, inviting atmosphere, making it ideal for daily living or peaceful escapes. | AA8: Additional Specs: In-Floor Waste Plumbing / Kiln Dried Framing Lumber / GFI Receptacle at all Wet Areas; Exterior Wall On Center: 16” O.C.; Exterior Wall Studs: 2'x6' Exterior Walls; Floor Decking: 19/32” OSB T&G Floor Decking; Floor Joists: 2x6 Floor Joists -16” O.C.; Roof Load: 30# Roof Load; Side Wall Height: 96” Sidewall (Flat Ceiling); Insulation (Floors): R-33; Insulation (Walls): R-21; Insulation (Ceiling): R-40 | AB8: Additional Specs: 2x8 Rough Sawn / Continuous Eave Soffit Venting / Ridge Style Roof Venting / Deadbolts on Front and Rear Doors; Front Door: 36” Front Doors; Rear Door: 36” Rear Doors; Roof Pitch: 3:12 (4:12 pitch single sections); Shingles: Architectural Shingles; Siding: LP Smart Panel Siding w/5/50 year warranty; Window Trim: 4” Window Trim; Window Type: Dual Pane Low-E Windows; Exterior Lighting: Porch Lights at each Exterior Entry; Front Rear Eaves: Exterior 14" Eaves Double wide, 6" Single wide; Exterior Outlets: Exterior 2 GFI Standard | AC8: Ceiling Texture: Brocade Style Ceiling Drywall Finish; Door Carpet Type: Entry Lino; Safety Alarms: Smoke Alarms, Bdrms & Living Areas; Window Type: Wood Window Interior Wrap / Egress Windows in all Bedrooms; Molding: Baseboard Molding in Lino Areas; Wall Finish: Tape and Texture Drywall Throughout / Square Sheetrock Corners; Interior Doors: 2-Panel Interior Doors; Carpet Type Or Grade: 5# Carpet Pad / New Wave 25oz Carpet | AD8: Electrical Service: 200 Amp Electrical Service; Electrical Wiring: All Copper Wiring; Furnace: Forced Air Elect Down Flow Furnace; Other: Receptacle at Fresh Water Inlet; Shut Off Valves Throughout: Whole House Shut-off Valve; Thermostat: EcoBee T-Stat; Washer Dryer Hook Up: Plumbed/Wire For Washer and Dryer; Water Heater: 40 Gallon Electric Water Heater; Water Shut Off Valves: Shut-Off Valves at Toilets & Sinks | AE8: Kitchen Sink: Kitchen Sink 8” Stainless Steel; Kitchen Refrigerator: Frigidaire 18 cu ft Refrigerator; Kitchen Range Type: Frigidaire Free Standing Range; Kitchen Range Hood: 30” Lighted Exhaust Fan over Range; Kitchen Lighting: Recessed Lights (Qty. Per Model); Kitchen Flooring: No-Wax Vinyl Flooring; Kitchen Faucets: Single Lever Faucet with Sprayer; Kitchen Countertops: Laminated Counter Tops / Crescent Edge T/Out; Kitchen Additional Specs: Fire Extinguisher Under Sink; Bathroom Sink: China Lavy Sinks; Bathroom Lighting: Recessed Lights (Per Model); Bathroom Flooring: No-Wax Vinyl Flooring; Bathroom Countertops: Laminated Counter Tops / Crescent Edge T/Out; Bathroom Faucets: Adjustable Shower Heads; Bathroom Fans: Exhaust Fans w/Light in each Bath; Bathroom Toilet Type: Elongated Toilets; Bathroom Bathtubs: 60” Fiberglass Tub/Shower in each Bath | AF8: Yes | AG8: Yes | AH8: Yes | AI8: =COUNTIF('Needs review'!$A:$A,B8) -> 0
A9: Dream Silver 601M | B9: gw-dream-silver-601m | C9: Golden West | D9: Dream Silver | E9: Standard | F9: Floorplan | G9: DRM 601M | I9: 2 | J9: 2 | K9: 810 | L9: 14 | M9: 60 | N9: Single | O9: 13' 6" WIDE | P9: Yes | S9: =IF(COUNTA(U9:W9)>0,"Yes","No") -> Yes | T9: https://raw.githubusercontent.com/CadelMVH/Wix-Gallery-Downloads/main/DRM/601M.pdf | U9: https://momento360.com/e/uc/cfb0e6eec7534aa0b42e80ae49f4de3d | X9: https://static.wixstatic.com/media/866235_dbbdc0ecf3d240509760767069035fd9~mv2.webp | Y9: https://static.wixstatic.com/media/866235_dbbdc0ecf3d240509760767069035fd9~mv2.webp; https://static.wixstatic.com/media/866235_556c72e3dc8b45d484c129c3cb75bfdf~mv2.webp | Z9: The Dream Silver / DRM 601M built by Golden West Homes provides 810 square feet of efficiently planned living space, featuring 2 bedrooms and 2 bathrooms. This manufactured home is thoughtfully designed to maximize comfort in a compact layout, with open living areas that enhance social spaces and private bedrooms that offer a restful retreat. The DRM 601M is an ideal choice for those seeking a modern, streamlined home that combines practicality with a welcoming atmosphere for daily living or weekend escapes. | AA9: Additional Specs: In-Floor Waste Plumbing / Kiln Dried Framing Lumber / GFI Receptacle at all Wet Areas; Exterior Wall On Center: 16” O.C.; Exterior Wall Studs: 2'x6' Exterior Walls; Floor Decking: 19/32” OSB T&G Floor Decking; Floor Joists: 2x6 Floor Joists -16” O.C.; Roof Load: 30# Roof Load; Side Wall Height: 96” Sidewall (Flat Ceiling); Insulation (Floors): R-33; Insulation (Walls): R-21; Insulation (Ceiling): R-40 | AB9: Additional Specs: 2x8 Rough Sawn / Continuous Eave Soffit Venting / Ridge Style Roof Venting / Deadbolts on Front and Rear Doors; Front Door: 36” Front Doors; Rear Door: 36” Rear Doors; Roof Pitch: 3:12 (4:12 pitch single sections); Shingles: Architectural Shingles; Siding: LP Smart Panel Siding w/5/50 year warranty; Window Trim: 4” Window Trim; Window Type: Dual Pane Low-E Windows; Exterior Lighting: Porch Lights at each Exterior Entry; Front Rear Eaves: Exterior 14" Eaves Double wide, 6" Single wide; Exterior Outlets: Exterior 2 GFI Standard | AC9: Ceiling Texture: Brocade Style Ceiling Drywall Finish; Door Carpet Type: Entry Lino; Safety Alarms: Smoke Alarms, Bdrms & Living Areas; Window Type: Wood Window Interior Wrap / Egress Windows in all Bedrooms; Molding: Baseboard Molding in Lino Areas; Wall Finish: Tape and Texture Drywall Throughout / Square Sheetrock Corners; Interior Doors: 2-Panel Interior Doors; Carpet Type Or Grade: 5# Carpet Pad / New Wave 25oz Carpet | AD9: Electrical Service: 200 Amp Electrical Service; Electrical Wiring: All Copper Wiring; Furnace: Forced Air Elect Down Flow Furnace; Other: Receptacle at Fresh Water Inlet; Shut Off Valves Throughout: Whole House Shut-off Valve; Thermostat: EcoBee T-Stat; Washer Dryer Hook Up: Plumbed/Wire For Washer and Dryer; Water Heater: 40 Gallon Electric Water Heater; Water Shut Off Valves: Shut-Off Valves at Toilets & Sinks | AE9: Kitchen Sink: Kitchen Sink 8” Stainless Steel; Kitchen Refrigerator: Frigidaire 18 cu ft Refrigerator; Kitchen Range Type: Frigidaire Free Standing Range; Kitchen Range Hood: 30” Lighted Exhaust Fan over Range; Kitchen Lighting: Recessed Lights (Qty. Per Model); Kitchen Flooring: No-Wax Vinyl Flooring; Kitchen Faucets: Single Lever Faucet with Sprayer; Kitchen Countertops: Laminated Counter Tops / Crescent Edge T/Out; Kitchen Additional Specs: Fire Extinguisher Under Sink; Bathroom Sink: China Lavy Sinks; Bathroom Lighting: Recessed Lights (Per Model); Bathroom Flooring: No-Wax Vinyl Flooring; Bathroom Countertops: Laminated Counter Tops / Crescent Edge T/Out; Bathroom Faucets: Adjustable Shower Heads; Bathroom Fans: Exhaust Fans w/Light in each Bath; Bathroom Toilet Type: Elongated Toilets; Bathroom Bathtubs: 60” Fiberglass Tub/Shower in each Bath | AF9: Yes | AG9: Yes | AH9: Yes | AI9: =COUNTIF('Needs review'!$A:$A,B9) -> 0
A10: Dream Silver 562N | B10: gw-dream-silver-562n | C10: Golden West | D10: Dream Silver | E10: Standard | F10: Floorplan | G10: DRM 562N | I10: 2 | J10: 1 | K10: 840 | L10: 15 | M10: 56 | N10: Single | O10: 15' WIDE | P10: Yes | S10: =IF(COUNTA(U10:W10)>0,"Yes","No") -> No | T10: https://raw.githubusercontent.com/CadelMVH/Wix-Gallery-Downloads/main/DRM/562N.pdf | X10: https://static.wixstatic.com/media/866235_a149c26ce06a4dcfa651138c560a6a6d~mv2.webp | Y10: https://static.wixstatic.com/media/866235_a149c26ce06a4dcfa651138c560a6a6d~mv2.webp; https://static.wixstatic.com/media/866235_8c79f14b1671461bb8e64794a46fb548~mv2.webp | Z10: The Dream Silver / DRM 562N built by Golden West Homes offers 840 square feet of efficiently utilized living space, featuring 2 bedrooms and 1 bathroom. This manufactured home is crafted for those who value both style and simplicity, with an open layout that enhances a sense of spaciousness and private bedrooms that provide a cozy retreat. The DRM 562N is an ideal choice for individuals or couples seeking a modern, compact home that combines comfort and functionality for seamless daily living. | AA10: Additional Specs: In-Floor Waste Plumbing / Kiln Dried Framing Lumber / GFI Receptacle at all Wet Areas; Exterior Wall On Center: 16” O.C.; Exterior Wall Studs: 2'x6' Exterior Walls; Floor Decking: 19/32” OSB T&G Floor Decking; Floor Joists: 2x6 Floor Joists -16” O.C.; Roof Load: 30# Roof Load; Side Wall Height: 96” Sidewall (Flat Ceiling); Insulation (Floors): R-33; Insulation (Walls): R-21; Insulation (Ceiling): R-40 | AB10: Additional Specs: 2x8 Rough Sawn / Continuous Eave Soffit Venting / Ridge Style Roof Venting / Deadbolts on Front and Rear Doors; Front Door: 36” Front Doors; Rear Door: 36” Rear Doors; Roof Pitch: 3:12 (4:12 pitch single sections); Shingles: Architectural Shingles; Siding: LP Smart Panel Siding w/5/50 year warranty; Window Trim: 4” Window Trim; Window Type: Dual Pane Low-E Windows; Exterior Lighting: Porch Lights at each Exterior Entry; Front Rear Eaves: Exterior 14" Eaves Double wide, 6" Single wide; Exterior Outlets: Exterior 2 GFI Standard | AC10: Ceiling Texture: Brocade Style Ceiling Drywall Finish; Door Carpet Type: Entry Lino; Safety Alarms: Smoke Alarms, Bdrms & Living Areas; Window Type: Wood Window Interior Wrap / Egress Windows in all Bedrooms; Molding: Baseboard Molding in Lino Areas; Wall Finish: Tape and Texture Drywall Throughout / Square Sheetrock Corners; Interior Doors: 2-Panel Interior Doors; Carpet Type Or Grade: 5# Carpet Pad / New Wave 25oz Carpet | AD10: Electrical Service: 200 Amp Electrical Service; Electrical Wiring: All Copper Wiring; Furnace: Forced Air Elect Down Flow Furnace; Other: Receptacle at Fresh Water Inlet; Shut Off Valves Throughout: Whole House Shut-off Valve; Thermostat: EcoBee T-Stat; Washer Dryer Hook Up: Plumbed/Wire For Washer and Dryer; Water Heater: 40 Gallon Electric Water Heater; Water Shut Off Valves: Shut-Off Valves at Toilets & Sinks | AE10: Kitchen Sink: Kitchen Sink 8” Stainless Steel; Kitchen Refrigerator: Frigidaire 18 cu ft Refrigerator; Kitchen Range Type: Frigidaire Free Standing Range; Kitchen Range Hood: 30” Lighted Exhaust Fan over Range; Kitchen Lighting: Recessed Lights (Qty. Per Model); Kitchen Flooring: No-Wax Vinyl Flooring; Kitchen Faucets: Single Lever Faucet with Sprayer; Kitchen Countertops: Laminated Counter Tops / Crescent Edge T/Out; Kitchen Additional Specs: Fire Extinguisher Under Sink; Bathroom Sink: China Lavy Sinks; Bathroom Lighting: Recessed Lights (Per Model); Bathroom Flooring: No-Wax Vinyl Flooring; Bathroom Countertops: Laminated Counter Tops / Crescent Edge T/Out; Bathroom Faucets: Adjustable Shower Heads; Bathroom Fans: Exhaust Fans w/Light in each Bath; Bathroom Toilet Type: Elongated Toilets; Bathroom Bathtubs: 60” Fiberglass Tub/Shower in each Bath | AF10: Yes | AG10: Yes | AH10: Yes | AI10: =COUNTIF('Needs review'!$A:$A,B10) -> 0
A11: Dream Silver 363A | B11: gw-dream-silver-363a | C11: Golden West | D11: Dream Silver | E11: Standard | F11: Floorplan | G11: DRM 363A | I11: 3 | J11: 2 | K11: 864 | L11: 24 | M11: 68 | N11: Double | O11: 24' WIDE | P11: No | Q11: bed/bath data may be wrong - verify | S11: =IF(COUNTA(U11:W11)>0,"Yes","No") -> No | T11: https://raw.githubusercontent.com/CadelMVH/Wix-Gallery-Downloads/main/DRM/363A.pdf | X11: https://static.wixstatic.com/media/866235_69eafe1a8326447b8e91d7dd6b2d369a~mv2.webp | Y11: https://static.wixstatic.com/media/866235_69eafe1a8326447b8e91d7dd6b2d369a~mv2.webp; https://static.wixstatic.com/media/866235_9ce0f58f0a614007b6cfb3b51f93e4be~mv2.webp | Z11: The Dream Silver / DRM 683F built by Golden West Albany is a beautifully crafted manufactured home offering 3 bedrooms, 2 bathrooms, and 1836 square feet of living space designed for comfort and ease. From its warm layout to its thoughtfully arranged features, this home is perfect for families ready to settle into something special. The DRM 683F delivers everyday functionality with a homestyle charm you’ll feel the moment you walk in. | AA11: Additional Specs: In-Floor Waste Plumbing / Kiln Dried Framing Lumber / GFI Receptacle at all Wet Areas; Exterior Wall On Center: 16” O.C.; Exterior Wall Studs: 2'x6' Exterior Walls; Floor Decking: 19/32” OSB T&G Floor Decking; Floor Joists: 2x6 Floor Joists -16” O.C.; Roof Load: 30# Roof Load; Side Wall Height: 96” Sidewall (Flat Ceiling); Insulation (Floors): R-33; Insulation (Walls): R-21; Insulation (Ceiling): R-40 | AB11: Additional Specs: 2x8 Rough Sawn / Continuous Eave Soffit Venting / Ridge Style Roof Venting / Deadbolts on Front and Rear Doors; Front Door: 36” Front Doors; Rear Door: 36” Rear Doors; Roof Pitch: 3:12 (4:12 pitch single sections); Shingles: Architectural Shingles; Siding: LP Smart Panel Siding w/5/50 year warranty; Window Trim: 4” Window Trim; Window Type: Dual Pane Low-E Windows; Exterior Lighting: Porch Lights at each Exterior Entry; Front Rear Eaves: Exterior 14" Eaves Double wide, 6" Single wide; Exterior Outlets: Exterior 2 GFI Standard | AC11: Ceiling Texture: Brocade Style Ceiling Drywall Finish; Door Carpet Type: Entry Lino; Safety Alarms: Smoke Alarms, Bdrms & Living Areas; Window Type: Wood Window Interior Wrap / Egress Windows in all Bedrooms; Molding: Baseboard Molding in Lino Areas; Wall Finish: Tape and Texture Drywall Throughout / Square Sheetrock Corners; Interior Doors: 2-Panel Interior Doors; Carpet Type Or Grade: 5# Carpet Pad / New Wave 25oz Carpet | AD11: Electrical Service: 200 Amp Electrical Service; Electrical Wiring: All Copper Wiring; Furnace: Forced Air Elect Down Flow Furnace; Other: Receptacle at Fresh Water Inlet; Shut Off Valves Throughout: Whole House Shut-off Valve; Thermostat: EcoBee T-Stat; Washer Dryer Hook Up: Plumbed/Wire For Washer and Dryer; Water Heater: 40 Gallon Electric Water Heater; Water Shut Off Valves: Shut-Off Valves at Toilets & Sinks | AE11: Kitchen Sink: Kitchen Sink 8” Stainless Steel; Kitchen Refrigerator: Frigidaire 18 cu ft Refrigerator; Kitchen Range Type: Frigidaire Free Standing Range; Kitchen Range Hood: 30” Lighted Exhaust Fan over Range; Kitchen Lighting: Recessed Lights (Qty. Per Model); Kitchen Flooring: No-Wax Vinyl Flooring; Kitchen Faucets: Single Lever Faucet with Sprayer; Kitchen Countertops: Laminated Counter Tops / Crescent Edge T/Out; Kitchen Additional Specs: Fire Extinguisher Under Sink; Bathroom Sink: China Lavy Sinks; Bathroom Lighting: Recessed Lights (Per Model); Bathroom Flooring: No-Wax Vinyl Flooring; Bathroom Countertops: Laminated Counter Tops / Crescent Edge T/Out; Bathroom Faucets: Adjustable Shower Heads; Bathroom Fans: Exhaust Fans w/Light in each Bath; Bathroom Toilet Type: Elongated Toilets; Bathroom Bathtubs: 60” Fiberglass Tub/Shower in each Bath | AF11: Yes | AG11: Yes | AH11: Yes | AI11: =COUNTIF('Needs review'!$A:$A,B11) -> 2
A12: Dream Silver 661M | B12: gw-dream-silver-661m | C12: Golden West | D12: Dream Silver | E12: Standard | F12: Floorplan | G12: DRM 661M | I12: 2 | J12: 2 | K12: 891 | L12: 14 | M12: 66 | N12: Single | O12: 13' 6" WIDE | P12: Yes | S12: =IF(COUNTA(U12:W12)>0,"Yes","No") -> No | T12: https://raw.githubusercontent.com/CadelMVH/Wix-Gallery-Downloads/main/DRM/661M.pdf | X12: https://static.wixstatic.com/media/866235_b685f715d7c346afaf26417c5c170e3d~mv2.webp | Y12: https://static.wixstatic.com/media/866235_b685f715d7c346afaf26417c5c170e3d~mv2.webp; https://static.wixstatic.com/media/866235_2f52c4f341c845e38f25d0f0b63efe47~mv2.webp | Z12: The Dream Silver / DRM 661M built by Golden West Homes offers 891 square feet of well-planned living space, featuring 2 bedrooms and 2 bathrooms. This manufactured home blends comfort and efficiency, with an open layout that enhances everyday functionality and private bedrooms that provide a relaxing retreat. The DRM 661M is an ideal choice for individuals or couples seeking a modern, compact home that combines style with practical living, making it perfect for daily life or as a peaceful getaway. | AA12: Additional Specs: In-Floor Waste Plumbing / Kiln Dried Framing Lumber / GFI Receptacle at all Wet Areas; Exterior Wall On Center: 16” O.C.; Exterior Wall Studs: 2'x6' Exterior Walls; Floor Decking: 19/32” OSB T&G Floor Decking; Floor Joists: 2x6 Floor Joists -16” O.C.; Roof Load: 30# Roof Load; Side Wall Height: 96” Sidewall (Flat Ceiling); Insulation (Floors): R-33; Insulation (Walls): R-21; Insulation (Ceiling): R-40 | AB12: Additional Specs: 2x8 Rough Sawn / Continuous Eave Soffit Venting / Ridge Style Roof Venting / Deadbolts on Front and Rear Doors; Front Door: 36” Front Doors; Rear Door: 36” Rear Doors; Roof Pitch: 3:12 (4:12 pitch single sections); Shingles: Architectural Shingles; Siding: LP Smart Panel Siding w/5/50 year warranty; Window Trim: 4” Window Trim; Window Type: Dual Pane Low-E Windows; Exterior Lighting: Porch Lights at each Exterior Entry; Front Rear Eaves: Exterior 14" Eaves Double wide, 6" Single wide; Exterior Outlets: Exterior 2 GFI Standard | AC12: Ceiling Texture: Brocade Style Ceiling Drywall Finish; Door Carpet Type: Entry Lino; Safety Alarms: Smoke Alarms, Bdrms & Living Areas; Window Type: Wood Window Interior Wrap / Egress Windows in all Bedrooms; Molding: Baseboard Molding in Lino Areas; Wall Finish: Tape and Texture Drywall Throughout / Square Sheetrock Corners; Interior Doors: 2-Panel Interior Doors; Carpet Type Or Grade: 5# Carpet Pad / New Wave 25oz Carpet | AD12: Electrical Service: 200 Amp Electrical Service; Electrical Wiring: All Copper Wiring; Furnace: Forced Air Elect Down Flow Furnace; Other: Receptacle at Fresh Water Inlet; Shut Off Valves Throughout: Whole House Shut-off Valve; Thermostat: EcoBee T-Stat; Washer Dryer Hook Up: Plumbed/Wire For Washer and Dryer; Water Heater: 40 Gallon Electric Water Heater; Water Shut Off Valves: Shut-Off Valves at Toilets & Sinks | AE12: Kitchen Sink: Kitchen Sink 8” Stainless Steel; Kitchen Refrigerator: Frigidaire 18 cu ft Refrigerator; Kitchen Range Type: Frigidaire Free Standing Range; Kitchen Range Hood: 30” Lighted Exhaust Fan over Range; Kitchen Lighting: Recessed Lights (Qty. Per Model); Kitchen Flooring: No-Wax Vinyl Flooring; Kitchen Faucets: Single Lever Faucet with Sprayer; Kitchen Countertops: Laminated Counter Tops / Crescent Edge T/Out; Kitchen Additional Specs: Fire Extinguisher Under Sink; Bathroom Sink: China Lavy Sinks; Bathroom Lighting: Recessed Lights (Per Model); Bathroom Flooring: No-Wax Vinyl Flooring; Bathroom Countertops: Laminated Counter Tops / Crescent Edge T/Out; Bathroom Faucets: Adjustable Shower Heads; Bathroom Fans: Exhaust Fans w/Light in each Bath; Bathroom Toilet Type: Elongated Toilets; Bathroom Bathtubs: 60” Fiberglass Tub/Shower in each Bath | AF12: Yes | AG12: Yes | AH12: Yes | AI12: =COUNTIF('Needs review'!$A:$A,B12) -> 0
A13: Dream Silver 385A | B13: gw-dream-silver-385a | C13: Golden West | D13: Dream Silver | E13: Standard | F13: Floorplan | G13: DRM 385A | I13: 3 | J13: 2 | K13: 900 | L13: 24 | M13: 38 | N13: Double | O13: 24' WIDE | P13: Yes | S13: =IF(COUNTA(U13:W13)>0,"Yes","No") -> Yes | T13: https://raw.githubusercontent.com/CadelMVH/Wix-Gallery-Downloads/main/DRM/385A.pdf | U13: https://momento360.com/e/uc/2128a17170fe41f8b3daa22400de4938 | X13: https://static.wixstatic.com/media/866235_dfc262e6bbb543619c63f9b647ba1a75~mv2.webp | Y13: https://static.wixstatic.com/media/866235_dfc262e6bbb543619c63f9b647ba1a75~mv2.webp; https://static.wixstatic.com/media/866235_f8b0d01fbe8645bb8eaefcfbbef53e4b~mv2.webp | Z13: The Dream Silver / DRM 385A built by Golden West Homes provides 900 square feet of intelligently designed living space, featuring 3 bedrooms and 2 bathrooms. This manufactured home balances comfort and efficiency, with an open layout ideal for gatherings and private bedrooms that create a serene retreat. The DRM 385A is an excellent choice for families or individuals seeking a compact, modern home that combines functionality with a cozy ambiance, making it perfect for both everyday living and relaxing downtime. | AA13: Additional Specs: In-Floor Waste Plumbing / Kiln Dried Framing Lumber / GFI Receptacle at all Wet Areas; Exterior Wall On Center: 16” O.C.; Exterior Wall Studs: 2'x6' Exterior Walls; Floor Decking: 19/32” OSB T&G Floor Decking; Floor Joists: 2x6 Floor Joists -16” O.C.; Roof Load: 30# Roof Load; Side Wall Height: 96” Sidewall (Flat Ceiling); Insulation (Floors): R-33; Insulation (Walls): R-21; Insulation (Ceiling): R-40 | AB13: Additional Specs: 2x8 Rough Sawn / Continuous Eave Soffit Venting / Ridge Style Roof Venting / Deadbolts on Front and Rear Doors; Front Door: 36” Front Doors; Rear Door: 36” Rear Doors; Roof Pitch: 3:12 (4:12 pitch single sections); Shingles: Architectural Shingles; Siding: LP Smart Panel Siding w/5/50 year warranty; Window Trim: 4” Window Trim; Window Type: Dual Pane Low-E Windows; Exterior Lighting: Porch Lights at each Exterior Entry; Front Rear Eaves: Exterior 14" Eaves Double wide, 6" Single wide; Exterior Outlets: Exterior 2 GFI Standard | AC13: Ceiling Texture: Brocade Style Ceiling Drywall Finish; Door Carpet Type: Entry Lino; Safety Alarms: Smoke Alarms, Bdrms & Living Areas; Window Type: Wood Window Interior Wrap / Egress Windows in all Bedrooms; Molding: Baseboard Molding in Lino Areas; Wall Finish: Tape and Texture Drywall Throughout / Square Sheetrock Corners; Interior Doors: 2-Panel Interior Doors; Carpet Type Or Grade: 5# Carpet Pad / New Wave 25oz Carpet | AD13: Electrical Service: 200 Amp Electrical Service; Electrical Wiring: All Copper Wiring; Furnace: Forced Air Elect Down Flow Furnace; Other: Receptacle at Fresh Water Inlet; Shut Off Valves Throughout: Whole House Shut-off Valve; Thermostat: EcoBee T-Stat; Washer Dryer Hook Up: Plumbed/Wire For Washer and Dryer; Water Heater: 40 Gallon Electric Water Heater; Water Shut Off Valves: Shut-Off Valves at Toilets & Sinks | AE13: Kitchen Sink: Kitchen Sink 8” Stainless Steel; Kitchen Refrigerator: Frigidaire 18 cu ft Refrigerator; Kitchen Range Type: Frigidaire Free Standing Range; Kitchen Range Hood: 30” Lighted Exhaust Fan over Range; Kitchen Lighting: Recessed Lights (Qty. Per Model); Kitchen Flooring: No-Wax Vinyl Flooring; Kitchen Faucets: Single Lever Faucet with Sprayer; Kitchen Countertops: Laminated Counter Tops / Crescent Edge T/Out; Kitchen Additional Specs: Fire Extinguisher Under Sink; Bathroom Sink: China Lavy Sinks; Bathroom Lighting: Recessed Lights (Per Model); Bathroom Flooring: No-Wax Vinyl Flooring; Bathroom Countertops: Laminated Counter Tops / Crescent Edge T/Out; Bathroom Faucets: Adjustable Shower Heads; Bathroom Fans: Exhaust Fans w/Light in each Bath; Bathroom Toilet Type: Elongated Toilets; Bathroom Bathtubs: 60” Fiberglass Tub/Shower in each Bath | AF13: Yes | AG13: Yes | AH13: Yes | AI13: =COUNTIF('Needs review'!$A:$A,B13) -> 0
A14: Dream Silver 386A | B14: gw-dream-silver-386a | C14: Golden West | D14: Dream Silver | E14: Standard | F14: Floorplan | G14: DRM 386A | I14: 2 | J14: 2 | K14: 900 | L14: 24 | M14: 38 | N14: Double | O14: 24' WIDE | P14: Yes | S14: =IF(COUNTA(U14:W14)>0,"Yes","No") -> Yes | T14: https://raw.githubusercontent.com/CadelMVH/Wix-Gallery-Downloads/main/DRM/386A.pdf | U14: https://momento360.com/e/uc/b08b4aaad98e4b1b8b72195780ff60ea | X14: https://static.wixstatic.com/media/866235_b7f76a018500498982e7f2a372c55cde~mv2.webp | Y14: https://static.wixstatic.com/media/866235_b7f76a018500498982e7f2a372c55cde~mv2.webp; https://static.wixstatic.com/media/866235_243b68aba82943b3a7d39b1e3383dc83~mv2.webp | Z14: The Dream Silver / DRM 386A built by Golden West Homes offers 900 square feet of efficiently arranged living space, featuring 2 bedrooms and 2 bathrooms. This manufactured home is crafted for those who value both comfort and practicality, with an open layout ideal for socializing and private bedrooms that provide a peaceful escape. The DRM 386A is an excellent choice for individuals or couples seeking a modern, compact home that combines functionality with a warm, inviting atmosphere, perfect for everyday living or retreats. | AA14: Additional Specs: In-Floor Waste Plumbing / Kiln Dried Framing Lumber / GFI Receptacle at all Wet Areas; Exterior Wall On Center: 16” O.C.; Exterior Wall Studs: 2'x6' Exterior Walls; Floor Decking: 19/32” OSB T&G Floor Decking; Floor Joists: 2x6 Floor Joists -16” O.C.; Roof Load: 30# Roof Load; Side Wall Height: 96” Sidewall (Flat Ceiling); Insulation (Floors): R-33; Insulation (Walls): R-21; Insulation (Ceiling): R-40 | AB14: Additional Specs: 2x8 Rough Sawn / Continuous Eave Soffit Venting / Ridge Style Roof Venting / Deadbolts on Front and Rear Doors; Front Door: 36” Front Doors; Rear Door: 36” Rear Doors; Roof Pitch: 3:12 (4:12 pitch single sections); Shingles: Architectural Shingles; Siding: LP Smart Panel Siding w/5/50 year warranty; Window Trim: 4” Window Trim; Window Type: Dual Pane Low-E Windows; Exterior Lighting: Porch Lights at each Exterior Entry; Front Rear Eaves: Exterior 14" Eaves Double wide, 6" Single wide; Exterior Outlets: Exterior 2 GFI Standard | AC14: Ceiling Texture: Brocade Style Ceiling Drywall Finish; Door Carpet Type: Entry Lino; Safety Alarms: Smoke Alarms, Bdrms & Living Areas; Window Type: Wood Window Interior Wrap / Egress Windows in all Bedrooms; Molding: Baseboard Molding in Lino Areas; Wall Finish: Tape and Texture Drywall Throughout / Square Sheetrock Corners; Interior Doors: 2-Panel Interior Doors; Carpet Type Or Grade: 5# Carpet Pad / New Wave 25oz Carpet | AD14: Electrical Service: 200 Amp Electrical Service; Electrical Wiring: All Copper Wiring; Furnace: Forced Air Elect Down Flow Furnace; Other: Receptacle at Fresh Water Inlet; Shut Off Valves Throughout: Whole House Shut-off Valve; Thermostat: EcoBee T-Stat; Washer Dryer Hook Up: Plumbed/Wire For Washer and Dryer; Water Heater: 40 Gallon Electric Water Heater; Water Shut Off Valves: Shut-Off Valves at Toilets & Sinks | AE14: Kitchen Sink: Kitchen Sink 8” Stainless Steel; Kitchen Refrigerator: Frigidaire 18 cu ft Refrigerator; Kitchen Range Type: Frigidaire Free Standing Range; Kitchen Range Hood: 30” Lighted Exhaust Fan over Range; Kitchen Lighting: Recessed Lights (Qty. Per Model); Kitchen Flooring: No-Wax Vinyl Flooring; Kitchen Faucets: Single Lever Faucet with Sprayer; Kitchen Countertops: Laminated Counter Tops / Crescent Edge T/Out; Kitchen Additional Specs: Fire Extinguisher Under Sink; Bathroom Sink: China Lavy Sinks; Bathroom Lighting: Recessed Lights (Per Model); Bathroom Flooring: No-Wax Vinyl Flooring; Bathroom Countertops: Laminated Counter Tops / Crescent Edge T/Out; Bathroom Faucets: Adjustable Shower Heads; Bathroom Fans: Exhaust Fans w/Light in each Bath; Bathroom Toilet Type: Elongated Toilets; Bathroom Bathtubs: 60” Fiberglass Tub/Shower in each Bath | AF14: Yes | AG14: Yes | AH14: Yes | AI14: =COUNTIF('Needs review'!$A:$A,B14) -> 0
A15: Dream Silver 603N | B15: gw-dream-silver-603n | C15: Golden West | D15: Dream Silver | E15: Standard | F15: Floorplan | G15: DRM 603N | I15: 2 | J15: 2 | K15: 900 | L15: 15 | M15: 60 | N15: Single | O15: 15' WIDE | P15: Yes | S15: =IF(COUNTA(U15:W15)>0,"Yes","No") -> Yes | T15: https://raw.githubusercontent.com/CadelMVH/Wix-Gallery-Downloads/main/DRM/603N.pdf | U15: https://momento360.com/e/uc/8442f5c46b424cae9ee1f4ce2b146044 | X15: https://static.wixstatic.com/media/866235_27250ba3b3ac4027b7a1d3094b6c69be~mv2.webp | Y15: https://static.wixstatic.com/media/866235_27250ba3b3ac4027b7a1d3094b6c69be~mv2.webp; https://static.wixstatic.com/media/866235_6561c9c84e7b4e08bb56fc30728c6218~mv2.webp | Z15: The Dream Silver / DRM 603N built by Golden West Homes offers 900 square feet of well-arranged living space, featuring 2 bedrooms and 2 bathrooms. This manufactured home combines modern design with efficiency, providing open living areas that encourage connection and private bedrooms for a cozy retreat. The DRM 603N is an ideal choice for individuals or couples seeking a home that balances functionality with contemporary style, making it perfect for those who appreciate comfort and smart space planning. | AA15: Additional Specs: In-Floor Waste Plumbing / Kiln Dried Framing Lumber / GFI Receptacle at all Wet Areas; Exterior Wall On Center: 16” O.C.; Exterior Wall Studs: 2'x6' Exterior Walls; Floor Decking: 19/32” OSB T&G Floor Decking; Floor Joists: 2x6 Floor Joists -16” O.C.; Roof Load: 30# Roof Load; Side Wall Height: 96” Sidewall (Flat Ceiling); Insulation (Floors): R-33; Insulation (Walls): R-21; Insulation (Ceiling): R-40 | AB15: Additional Specs: 2x8 Rough Sawn / Continuous Eave Soffit Venting / Ridge Style Roof Venting / Deadbolts on Front and Rear Doors; Front Door: 36” Front Doors; Rear Door: 36” Rear Doors; Roof Pitch: 3:12 (4:12 pitch single sections); Shingles: Architectural Shingles; Siding: LP Smart Panel Siding w/5/50 year warranty; Window Trim: 4” Window Trim; Window Type: Dual Pane Low-E Windows; Exterior Lighting: Porch Lights at each Exterior Entry; Front Rear Eaves: Exterior 14" Eaves Double wide, 6" Single wide; Exterior Outlets: Exterior 2 GFI Standard | AC15: Ceiling Texture: Brocade Style Ceiling Drywall Finish; Door Carpet Type: Entry Lino; Safety Alarms: Smoke Alarms, Bdrms & Living Areas; Window Type: Wood Window Interior Wrap / Egress Windows in all Bedrooms; Molding: Baseboard Molding in Lino Areas; Wall Finish: Tape and Texture Drywall Throughout / Square Sheetrock Corners; Interior Doors: 2-Panel Interior Doors; Carpet Type Or Grade: 5# Carpet Pad / New Wave 25oz Carpet | AD15: Electrical Service: 200 Amp Electrical Service; Electrical Wiring: All Copper Wiring; Furnace: Forced Air Elect Down Flow Furnace; Other: Receptacle at Fresh Water Inlet; Shut Off Valves Throughout: Whole House Shut-off Valve; Thermostat: EcoBee T-Stat; Washer Dryer Hook Up: Plumbed/Wire For Washer and Dryer; Water Heater: 40 Gallon Electric Water Heater; Water Shut Off Valves: Shut-Off Valves at Toilets & Sinks | AE15: Kitchen Sink: Kitchen Sink 8” Stainless Steel; Kitchen Refrigerator: Frigidaire 18 cu ft Refrigerator; Kitchen Range Type: Frigidaire Free Standing Range; Kitchen Range Hood: 30” Lighted Exhaust Fan over Range; Kitchen Lighting: Recessed Lights (Qty. Per Model); Kitchen Flooring: No-Wax Vinyl Flooring; Kitchen Faucets: Single Lever Faucet with Sprayer; Kitchen Countertops: Laminated Counter Tops / Crescent Edge T/Out; Kitchen Additional Specs: Fire Extinguisher Under Sink; Bathroom Sink: China Lavy Sinks; Bathroom Lighting: Recessed Lights (Per Model); Bathroom Flooring: No-Wax Vinyl Flooring; Bathroom Countertops: Laminated Counter Tops / Crescent Edge T/Out; Bathroom Faucets: Adjustable Shower Heads; Bathroom Fans: Exhaust Fans w/Light in each Bath; Bathroom Toilet Type: Elongated Toilets; Bathroom Bathtubs: 60” Fiberglass Tub/Shower in each Bath | AF15: Yes | AG15: Yes | AH15: Yes | AI15: =COUNTIF('Needs review'!$A:$A,B15) -> 0
